[2022-05-24 12:44:44,608] {taskinstance.py:1159} INFO - Dependencies all met for <TaskInstance: book_db.check_api scheduled__2022-05-23T00:00:00+00:00 [queued]>
[2022-05-24 12:44:44,663] {taskinstance.py:1159} INFO - Dependencies all met for <TaskInstance: book_db.check_api scheduled__2022-05-23T00:00:00+00:00 [queued]>
[2022-05-24 12:44:44,664] {taskinstance.py:1356} INFO - 
--------------------------------------------------------------------------------
[2022-05-24 12:44:44,666] {taskinstance.py:1357} INFO - Starting attempt 1 of 1
[2022-05-24 12:44:44,667] {taskinstance.py:1358} INFO - 
--------------------------------------------------------------------------------
[2022-05-24 12:44:44,696] {taskinstance.py:1377} INFO - Executing <Task(HttpSensor): check_api> on 2022-05-23 00:00:00+00:00
[2022-05-24 12:44:44,710] {standard_task_runner.py:52} INFO - Started process 195 to run task
[2022-05-24 12:44:44,723] {standard_task_runner.py:79} INFO - Running: ['***', 'tasks', 'run', 'book_db', 'check_api', 'scheduled__2022-05-23T00:00:00+00:00', '--job-id', '5', '--raw', '--subdir', 'DAGS_FOLDER/books_db.py', '--cfg-path', '/tmp/tmpk45w613_', '--error-file', '/tmp/tmpmwk5jyjj']
[2022-05-24 12:44:44,725] {standard_task_runner.py:80} INFO - Job 5: Subtask check_api
[2022-05-24 12:44:44,902] {task_command.py:369} INFO - Running <TaskInstance: book_db.check_api scheduled__2022-05-23T00:00:00+00:00 [running]> on host ac29b12a0730
[2022-05-24 12:44:45,104] {taskinstance.py:1571} INFO - Exporting the following env vars:
AIRFLOW_CTX_DAG_OWNER=***
AIRFLOW_CTX_DAG_ID=book_db
AIRFLOW_CTX_TASK_ID=check_api
AIRFLOW_CTX_EXECUTION_DATE=2022-05-23T00:00:00+00:00
AIRFLOW_CTX_TRY_NUMBER=1
AIRFLOW_CTX_DAG_RUN_ID=scheduled__2022-05-23T00:00:00+00:00
[2022-05-24 12:44:45,107] {http.py:97} INFO - Poking: new
[2022-05-24 12:44:45,149] {taskinstance.py:1889} ERROR - Task failed with exception
Traceback (most recent call last):
  File "/home/airflow/.local/lib/python3.7/site-packages/airflow/sensors/base.py", line 277, in execute
    poke_return = self.poke(context)
  File "/home/airflow/.local/lib/python3.7/site-packages/airflow/providers/http/sensors/http.py", line 112, in poke
    raise exc
  File "/home/airflow/.local/lib/python3.7/site-packages/airflow/providers/http/sensors/http.py", line 103, in poke
    extra_options=self.extra_options,
  File "/home/airflow/.local/lib/python3.7/site-packages/airflow/providers/http/hooks/http.py", line 114, in run
    session = self.get_conn(headers)
  File "/home/airflow/.local/lib/python3.7/site-packages/airflow/providers/http/hooks/http.py", line 68, in get_conn
    conn = self.get_connection(self.http_conn_id)
  File "/home/airflow/.local/lib/python3.7/site-packages/airflow/hooks/base.py", line 67, in get_connection
    conn = Connection.get_connection_from_secrets(conn_id)
  File "/home/airflow/.local/lib/python3.7/site-packages/airflow/models/connection.py", line 430, in get_connection_from_secrets
    raise AirflowNotFoundException(f"The conn_id `{conn_id}` isn't defined")
airflow.exceptions.AirflowNotFoundException: The conn_id `book_api` isn't defined
[2022-05-24 12:44:45,171] {taskinstance.py:1400} INFO - Marking task as FAILED. dag_id=book_db, task_id=check_api, execution_date=20220523T000000, start_date=20220524T124444, end_date=20220524T124445
[2022-05-24 12:44:45,210] {standard_task_runner.py:97} ERROR - Failed to execute job 5 for task check_api (The conn_id `book_api` isn't defined; 195)
[2022-05-24 12:44:45,254] {local_task_job.py:156} INFO - Task exited with return code 1
[2022-05-24 12:44:45,324] {local_task_job.py:273} INFO - 0 downstream tasks scheduled from follow-on schedule check
