[2022-05-26 21:01:32,238] {taskinstance.py:1159} INFO - Dependencies all met for <TaskInstance: trigger_rule.task_7 scheduled__2022-05-24T00:00:00+00:00 [queued]>
[2022-05-26 21:01:32,446] {taskinstance.py:1159} INFO - Dependencies all met for <TaskInstance: trigger_rule.task_7 scheduled__2022-05-24T00:00:00+00:00 [queued]>
[2022-05-26 21:01:32,468] {taskinstance.py:1356} INFO - 
--------------------------------------------------------------------------------
[2022-05-26 21:01:32,493] {taskinstance.py:1357} INFO - Starting attempt 1 of 1
[2022-05-26 21:01:32,498] {taskinstance.py:1358} INFO - 
--------------------------------------------------------------------------------
[2022-05-26 21:01:32,839] {taskinstance.py:1377} INFO - Executing <Task(BashOperator): task_7> on 2022-05-24 00:00:00+00:00
[2022-05-26 21:01:32,966] {standard_task_runner.py:52} INFO - Started process 566 to run task
[2022-05-26 21:01:33,061] {standard_task_runner.py:79} INFO - Running: ['***', 'tasks', 'run', 'trigger_rule', 'task_7', 'scheduled__2022-05-24T00:00:00+00:00', '--job-id', '17', '--raw', '--subdir', 'DAGS_FOLDER/trigger_rule.py', '--cfg-path', '/tmp/tmphy15p8xo', '--error-file', '/tmp/tmpqatu44ca']
[2022-05-26 21:01:33,086] {standard_task_runner.py:80} INFO - Job 17: Subtask task_7
[2022-05-26 21:01:34,595] {task_command.py:369} INFO - Running <TaskInstance: trigger_rule.task_7 scheduled__2022-05-24T00:00:00+00:00 [running]> on host 2fe522ea8532
[2022-05-26 21:01:35,870] {taskinstance.py:1571} INFO - Exporting the following env vars:
AIRFLOW_CTX_DAG_OWNER=***
AIRFLOW_CTX_DAG_ID=trigger_rule
AIRFLOW_CTX_TASK_ID=task_7
AIRFLOW_CTX_EXECUTION_DATE=2022-05-24T00:00:00+00:00
AIRFLOW_CTX_TRY_NUMBER=1
AIRFLOW_CTX_DAG_RUN_ID=scheduled__2022-05-24T00:00:00+00:00
[2022-05-26 21:01:35,885] {subprocess.py:62} INFO - Tmp dir root location: 
 /tmp
[2022-05-26 21:01:35,902] {subprocess.py:74} INFO - Running command: ['bash', '-c', 'sleep 1']
[2022-05-26 21:01:36,173] {subprocess.py:85} INFO - Output:
[2022-05-26 21:01:37,262] {subprocess.py:96} INFO - Command exited with return code 0
[2022-05-26 21:01:37,443] {local_task_job.py:84} ERROR - Received SIGTERM. Terminating subprocesses
[2022-05-26 21:01:37,549] {process_utils.py:129} INFO - Sending Signals.SIGTERM to group 566. PIDs of all processes in the group: [566]
[2022-05-26 21:01:37,555] {process_utils.py:80} INFO - Sending the signal Signals.SIGTERM to group 566
[2022-05-26 21:01:37,576] {taskinstance.py:1541} ERROR - Received SIGTERM. Terminating subprocesses.
[2022-05-26 21:01:37,629] {subprocess.py:103} INFO - Sending SIGTERM signal to process group
[2022-05-26 21:01:37,833] {taskinstance.py:1889} ERROR - Task failed with exception
Traceback (most recent call last):
  File "/home/airflow/.local/lib/python3.7/site-packages/sqlalchemy/engine/base.py", line 1706, in _execute_context
    cursor, statement, parameters, context
  File "/home/airflow/.local/lib/python3.7/site-packages/sqlalchemy/engine/default.py", line 716, in do_execute
    cursor.execute(statement, parameters)
psycopg2.OperationalError: terminating connection due to administrator command
server closed the connection unexpectedly
	This probably means the server terminated abnormally
	before or while processing the request.


During handling of the above exception, another exception occurred:

Traceback (most recent call last):
  File "/home/airflow/.local/lib/python3.7/site-packages/airflow/utils/session.py", line 68, in wrapper
    return func(*args, **kwargs)
  File "/home/airflow/.local/lib/python3.7/site-packages/airflow/models/taskinstance.py", line 2380, in xcom_push
    session=session,
  File "/home/airflow/.local/lib/python3.7/site-packages/airflow/utils/session.py", line 68, in wrapper
    return func(*args, **kwargs)
  File "/home/airflow/.local/lib/python3.7/site-packages/airflow/models/xcom.py", line 187, in set
    dag_run_id = session.query(DagRun.id).filter_by(dag_id=dag_id, run_id=run_id).scalar()
  File "/home/airflow/.local/lib/python3.7/site-packages/sqlalchemy/orm/query.py", line 2803, in scalar
    ret = self.one()
  File "/home/airflow/.local/lib/python3.7/site-packages/sqlalchemy/orm/query.py", line 2780, in one
    return self._iter().one()
  File "/home/airflow/.local/lib/python3.7/site-packages/sqlalchemy/orm/query.py", line 2821, in _iter
    execution_options={"_sa_orm_load_options": self.load_options},
  File "/home/airflow/.local/lib/python3.7/site-packages/sqlalchemy/orm/session.py", line 1670, in execute
    result = conn._execute_20(statement, params or {}, execution_options)
  File "/home/airflow/.local/lib/python3.7/site-packages/sqlalchemy/engine/base.py", line 1520, in _execute_20
    return meth(self, args_10style, kwargs_10style, execution_options)
  File "/home/airflow/.local/lib/python3.7/site-packages/sqlalchemy/sql/elements.py", line 314, in _execute_on_connection
    self, multiparams, params, execution_options
  File "/home/airflow/.local/lib/python3.7/site-packages/sqlalchemy/engine/base.py", line 1399, in _execute_clauseelement
    cache_hit=cache_hit,
  File "/home/airflow/.local/lib/python3.7/site-packages/sqlalchemy/engine/base.py", line 1749, in _execute_context
    e, statement, parameters, cursor, context
  File "/home/airflow/.local/lib/python3.7/site-packages/sqlalchemy/engine/base.py", line 1857, in _handle_dbapi_exception
    sqlalchemy_exception = exc.DBAPIError.instance(
  File "/home/airflow/.local/lib/python3.7/site-packages/airflow/models/taskinstance.py", line 1542, in signal_handler
    self.task.on_kill()
  File "/home/airflow/.local/lib/python3.7/site-packages/airflow/operators/bash.py", line 200, in on_kill
    self.subprocess_hook.send_sigterm()
  File "/home/airflow/.local/lib/python3.7/site-packages/airflow/hooks/subprocess.py", line 105, in send_sigterm
    os.killpg(os.getpgid(self.sub_process.pid), signal.SIGTERM)
ProcessLookupError: [Errno 3] No such process
[2022-05-26 21:01:38,590] {standard_task_runner.py:97} ERROR - Failed to execute job 17 for task task_7 ((psycopg2.OperationalError) could not translate host name "postgres" to address: Name or service not known

(Background on this error at: http://sqlalche.me/e/14/e3q8); 566)
[2022-05-26 21:01:39,810] {process_utils.py:75} INFO - Process psutil.Process(pid=566, status='terminated', exitcode=1, started='21:01:32') (566) terminated with exit code 1
[2022-05-26 21:01:39,812] {local_task_job.py:156} INFO - Task exited with return code 143
