[2022-05-31 16:38:16,695] {taskinstance.py:1159} INFO - Dependencies all met for <TaskInstance: book_db.check_api manual__2022-05-31T16:38:08.051690+00:00 [queued]>
[2022-05-31 16:38:16,804] {taskinstance.py:1159} INFO - Dependencies all met for <TaskInstance: book_db.check_api manual__2022-05-31T16:38:08.051690+00:00 [queued]>
[2022-05-31 16:38:16,807] {taskinstance.py:1356} INFO - 
--------------------------------------------------------------------------------
[2022-05-31 16:38:16,811] {taskinstance.py:1357} INFO - Starting attempt 1 of 1
[2022-05-31 16:38:16,829] {taskinstance.py:1358} INFO - 
--------------------------------------------------------------------------------
[2022-05-31 16:38:16,991] {taskinstance.py:1377} INFO - Executing <Task(HttpSensor): check_api> on 2022-05-31 16:38:08.051690+00:00
[2022-05-31 16:38:17,053] {standard_task_runner.py:79} INFO - Running: ['***', 'tasks', 'run', 'book_db', 'check_api', 'manual__2022-05-31T16:38:08.051690+00:00', '--job-id', '6', '--raw', '--subdir', 'DAGS_FOLDER/books_db.py', '--cfg-path', '/tmp/tmpzrm0pqo8', '--error-file', '/tmp/tmprfoslk5e']
[2022-05-31 16:38:17,057] {standard_task_runner.py:80} INFO - Job 6: Subtask check_api
[2022-05-31 16:38:17,032] {standard_task_runner.py:52} INFO - Started process 223 to run task
[2022-05-31 16:38:17,531] {task_command.py:369} INFO - Running <TaskInstance: book_db.check_api manual__2022-05-31T16:38:08.051690+00:00 [running]> on host c713a0714fa8
[2022-05-31 16:38:18,399] {taskinstance.py:1571} INFO - Exporting the following env vars:
AIRFLOW_CTX_DAG_OWNER=***
AIRFLOW_CTX_DAG_ID=book_db
AIRFLOW_CTX_TASK_ID=check_api
AIRFLOW_CTX_EXECUTION_DATE=2022-05-31T16:38:08.051690+00:00
AIRFLOW_CTX_TRY_NUMBER=1
AIRFLOW_CTX_DAG_RUN_ID=manual__2022-05-31T16:38:08.051690+00:00
[2022-05-31 16:38:18,406] {http.py:97} INFO - Poking: new
[2022-05-31 16:38:18,578] {base.py:68} INFO - Using connection ID 'book_api' for task execution.
[2022-05-31 16:38:18,622] {http.py:129} INFO - Sending 'GET' to url: https://api.itbook.store/1.0/new/new
[2022-05-31 16:38:20,353] {http.py:142} ERROR - HTTP error: Not Found
[2022-05-31 16:38:20,355] {http.py:143} ERROR - <!DOCTYPE HTML PUBLIC "-//IETF//DTD HTML 2.0//EN">
<html><head>
<title>404 Not Found</title>
</head><body>
<h1>Not Found</h1>
<p>The requested URL /1.0/new/new was not found on this server.</p>
<p>Additionally, a 404 Not Found
error was encountered while trying to use an ErrorDocument to handle the request.</p>
</body></html>

[2022-05-31 16:39:20,399] {http.py:97} INFO - Poking: new
[2022-05-31 16:39:20,463] {base.py:68} INFO - Using connection ID 'book_api' for task execution.
[2022-05-31 16:39:20,467] {http.py:129} INFO - Sending 'GET' to url: https://api.itbook.store/1.0/new/new
[2022-05-31 16:39:21,238] {http.py:142} ERROR - HTTP error: Not Found
[2022-05-31 16:39:21,242] {http.py:143} ERROR - <!DOCTYPE HTML PUBLIC "-//IETF//DTD HTML 2.0//EN">
<html><head>
<title>404 Not Found</title>
</head><body>
<h1>Not Found</h1>
<p>The requested URL /1.0/new/new was not found on this server.</p>
<p>Additionally, a 404 Not Found
error was encountered while trying to use an ErrorDocument to handle the request.</p>
</body></html>

[2022-05-31 16:40:21,291] {http.py:97} INFO - Poking: new
[2022-05-31 16:40:21,317] {base.py:68} INFO - Using connection ID 'book_api' for task execution.
[2022-05-31 16:40:21,319] {http.py:129} INFO - Sending 'GET' to url: https://api.itbook.store/1.0/new
[2022-05-31 16:40:22,474] {base.py:301} INFO - Success criteria met. Exiting.
[2022-05-31 16:40:22,506] {taskinstance.py:1400} INFO - Marking task as SUCCESS. dag_id=book_db, task_id=check_api, execution_date=20220531T163808, start_date=20220531T163816, end_date=20220531T164022
[2022-05-31 16:40:22,633] {local_task_job.py:156} INFO - Task exited with return code 0
[2022-05-31 16:40:22,834] {local_task_job.py:273} INFO - 1 downstream tasks scheduled from follow-on schedule check
